<?xml version="1.0" ?>
<sdf version="1.10">
    <world name="car_world">
        <physics name="1ms" type="ignored">
            <max_step_size>0.001</max_step_size>
            <real_time_factor>1.0</real_time_factor>
        </physics>
        <plugin
            filename="gz-sim-physics-system"
            name="gz::sim::systems::Physics">
        </plugin>
        <plugin
            filename="gz-sim-user-commands-system"
            name="gz::sim::systems::UserCommands">
        </plugin>
        <plugin
			filename="gz-sim-scene-broadcaster-system"
            name="gz::sim::systems::SceneBroadcaster">
        </plugin>
        
        <plugin
    		filename="gz-sim-sensors-system"
    		name="gz::sim::systems::Sensors">
    		<render_engine>ogre2</render_engine>
    	</plugin>

        <light type="directional" name="sun">
            <cast_shadows>false</cast_shadows>
            <pose>0 0 10 0 0 0</pose>
            <diffuse>0.8 0.8 0.8 1</diffuse>
            <specular>0.2 0.2 0.2 1</specular>
            <attenuation>
                <range>1000</range>
                <constant>0.9</constant>
                <linear>0.01</linear>
                <quadratic>0.001</quadratic>
            </attenuation>
            <direction>-0.5 0.1 -0.9</direction>
        </light>

        <model name="ground_plane">
            <static>true</static>
            <link name="link">
                <collision name="collision">
                <geometry>
                    <plane>
                    <normal>0 0 1</normal>
                    </plane>
                </geometry>
                </collision>
                <visual name="visual">
                <geometry>
                    <plane>
                    <normal>0 0 1</normal>
                    <size>1000 1000</size>
                    </plane>
                </geometry>
                <material>
                    <ambient>0.8 0.8 0.8 1</ambient>
                    <diffuse>0.8 0.8 0.8 1</diffuse>
                    <specular>0.8 0.8 0.8 1</specular>
                </material>
                </visual>
            </link>
        </model>
        <model name='vehicle_blue' canonical_link='chassis'>
    		<pose relative_to='world'>0 0 0 0 0 0</pose>
    		<link name='chassis'>
        		<pose relative_to='__model__'>0.5 0 0.4 0 0 0</pose>
        	    <inertial> <!--inertial properties of the link mass, inertia matix-->
        			<mass>1.14395</mass>
        			<inertia>
            			<ixx>0.095329</ixx>
            			<ixy>0</ixy>
            			<ixz>0</ixz>
            			<iyy>0.381317</iyy>
            			<iyz>0</iyz>
            			<izz>0.476646</izz>
        			</inertia>
    			</inertial>
    			<visual name='visual'>
        			<geometry>
            			<box>
                			<size>2.0 1.0 0.5</size>
            			</box>
        			</geometry>
        		<!--let's add color to our link-->
        			<material>
            			<ambient>0.0 0.0 1.0 1</ambient>
            			<diffuse>0.0 0.0 1.0 1</diffuse>
            			<specular>0.0 0.0 1.0 1</specular>
        			</material>
    			</visual>
    			<collision name='collision'>
            		<geometry>
                		<box>
                    		<size>2.0 1.0 0.5</size>
                		</box>
            		</geometry>
        		</collision>
    		</link>
    		
    		<link name="lidar_housing">
    			<!-- Pozycja cylindra na dachu podwozia -->
    			<pose relative_to='chassis'>0 0 0.3 0 0 0</pose>
    
    			<inertial>
        			<mass>0.2</mass>
        			<inertia>
            			<ixx>0.02</ixx>
            			<ixy>0</ixy>
            			<ixz>0</ixz>
            			<iyy>0.02</iyy>
            			<iyz>0</iyz>
            			<izz>0.02</izz>
        			</inertia>
    			</inertial>
    
    			<visual name='lidar_cylinder'>
        			<geometry>
            			<cylinder>
                			<radius>0.3</radius>
                			<length>0.5</length>
            			</cylinder>
        			</geometry>
        			<material>
            			<ambient>0.5 0.5 0.5 1</ambient>
            			<diffuse>0.5 0.5 0.5 1</diffuse>
            			<specular>0.5 0.5 0.5 1</specular>
        			</material>
    			</visual>
    
    			<collision name='collision'>
        			<geometry>
            			<cylinder>
                			<radius>0.3</radius>
                			<length>0.5</length>
            			</cylinder>
        			</geometry>
    			</collision>
    
    			<!-- Zamontowany LIDAR -->
    			<sensor name='gpu_lidar' type='gpu_lidar'>
        			<pose>0 0 0.2 0 0 0</pose>
        			<topic>lidar</topic>
        			<update_rate>10</update_rate>
        			<ray>
            			<scan>
                			<horizontal>
                    			<samples>640</samples>
                    			<resolution>1</resolution>
                    			<min_angle>-3.141593</min_angle>
                    			<max_angle>3.141593</max_angle>
                			</horizontal>
                			<vertical>
                    			<samples>1</samples>
                    			<resolution>0.01</resolution>
                    			<min_angle>0</min_angle>
                    			<max_angle>0</max_angle>
                			</vertical>
            			</scan>
            			<range>
                			<min>0.08</min>
                			<max>10.0</max>
                			<resolution>0.01</resolution>
            			</range>
        			</ray>
        			<always_on>1</always_on>
        			<visualize>true</visualize>
    			</sensor>
			</link>
    		
    		<!-- left wheel link -->
    		<link name='left_wheel'>
    			<pose relative_to="chassis">-0.5 0.6 0 -1.5707 0 0</pose>
    			<inertial>
        			<mass>1</mass>
        			<inertia>
            			<ixx>0.043333</ixx>
            			<ixy>0</ixy>
            			<ixz>0</ixz>
            			<iyy>0.043333</iyy>
            			<iyz>0</iyz>
            			<izz>0.08</izz>
        			</inertia>
    			</inertial>
    			<visual name='visual'>
        			<geometry>
            			<cylinder>
                			<radius>0.4</radius>
                			<length>0.2</length>
            			</cylinder>
        			</geometry>
        			<material>
            			<ambient>1.0 0.0 0.0 1</ambient>
            			<diffuse>1.0 0.0 0.0 1</diffuse>
            			<specular>1.0 0.0 0.0 1</specular>
        			</material>
    			</visual>
    			<collision name='collision'>
        			<geometry>
            			<cylinder>
                			<radius>0.4</radius>
                			<length>0.2</length>
            			</cylinder>
        			</geometry>
    			</collision>
			</link>
			
			<!--The same as left wheel but with different position-->
			<link name='right_wheel'>
    			<pose relative_to="chassis">-0.5 -0.6 0 -1.5707 0 0</pose> 
    			<!--angles are in radian-->
    			<inertial>
        			<mass>1</mass>
        			<inertia>
            			<ixx>0.043333</ixx>
            			<ixy>0</ixy>
            			<ixz>0</ixz>
            			<iyy>0.043333</iyy>
            			<iyz>0</iyz>
            			<izz>0.08</izz>
        			</inertia>
    			</inertial>
    			<visual name='visual'>
        			<geometry>
            			<cylinder>
                			<radius>0.4</radius>
                			<length>0.2</length>
            			</cylinder>
        			</geometry>
        			<material>
            			<ambient>1.0 0.0 0.0 1</ambient>
            			<diffuse>1.0 0.0 0.0 1</diffuse>
            			<specular>1.0 0.0 0.0 1</specular>
        			</material>
    			</visual>
    			<collision name='collision'>
        			<geometry>
            			<cylinder>
                			<radius>0.4</radius>
                			<length>0.2</length>
            			</cylinder>
        			</geometry>
    			</collision>
			</link>
			
			<frame name="caster_frame" attached_to='chassis'>
    			<pose>0.8 0 -0.2 0 0 0</pose>
			</frame>
			
			<!--caster wheel-->
			<link name='caster'>
    			<pose relative_to='caster_frame'/>
    			<inertial>
        			<mass>1</mass>
        			<inertia>
            			<ixx>0.016</ixx>
            			<ixy>0</ixy>
            			<ixz>0</ixz>
            			<iyy>0.016</iyy>
            			<iyz>0</iyz>
            			<izz>0.016</izz>
        			</inertia>
    			</inertial>
    			<visual name='visual'>
        			<geometry>
            			<sphere>
                			<radius>0.2</radius>
            			</sphere>
        			</geometry>
        			<material>
            			<ambient>0.0 1 0.0 1</ambient>
            			<diffuse>0.0 1 0.0 1</diffuse>
            			<specular>0.0 1 0.0 1</specular>
        			</material>
    			</visual>
    			<collision name='collision'>
        			<geometry>
            			<sphere>
                			<radius>0.2</radius>
            			</sphere>
        			</geometry>
    			</collision>
			</link>
			
			<joint name='left_wheel_joint' type='revolute'>
    			<pose relative_to='left_wheel'/>
    			<parent>chassis</parent>
    			<child>left_wheel</child>
    			<axis>
        			<xyz expressed_in='__model__'>0 1 0</xyz> 
        			<!--can be defined as any frame or even arbitrary frames-->
        			<limit>
            			<lower>-1.79769e+308</lower>    <!--negative infinity-->
            			<upper>1.79769e+308</upper>     <!--positive infinity-->
        			</limit>
    			</axis>
			</joint>
			
			<joint name='right_wheel_joint' type='revolute'>
    			<pose relative_to='right_wheel'/>
    			<parent>chassis</parent>
    			<child>right_wheel</child>
    			<axis>
        			<xyz expressed_in='__model__'>0 1 0</xyz>
        			<limit>
            			<lower>-1.79769e+308</lower>    <!--negative infinity-->
            			<upper>1.79769e+308</upper>     <!--positive infinity-->
        			</limit>
    			</axis>
			</joint>
			
			<joint name='caster_wheel' type='ball'>
    			<parent>chassis</parent>
    			<child>caster</child>
			</joint>
			
			<joint name="lidar_fixed_joint" type="fixed">
    			<parent>chassis</parent>
    			<child>lidar_housing</child>
    			<pose>0 0 0.9 0 0 0</pose>
			</joint>
			<plugin
    			filename="gz-sim-diff-drive-system"
    			name="gz::sim::systems::DiffDrive">
    			<left_joint>left_wheel_joint</left_joint>
    			<right_joint>right_wheel_joint</right_joint>
    			<wheel_separation>1.2</wheel_separation>
    			<wheel_radius>0.4</wheel_radius>
    			<odom_publish_frequency>1</odom_publish_frequency>
    			<topic>cmd_vel</topic>
			</plugin>
			
			<!-- Moving Forward-->
			<plugin filename="gz-sim-triggered-publisher-system"
        			name="gz::sim::systems::TriggeredPublisher">
    			<input type="gz.msgs.Int32" topic="/keyboard/keypress">
        			<match field="data">16777235</match>
    			</input>
    			<output type="gz.msgs.Twist" topic="/cmd_vel">
        			linear: {x: 0.5}, angular: {z: 0.0}
    			</output>
			</plugin>
			
						<!-- Moving Backward-->
			<plugin filename="gz-sim-triggered-publisher-system"
        			name="gz::sim::systems::TriggeredPublisher">
    			<input type="gz.msgs.Int32" topic="/keyboard/keypress">
        			<match field="data">16777237</match>
    			</input>
    			<output type="gz.msgs.Twist" topic="/cmd_vel">
        			linear: {x: -0.5}, angular: {z: 0.0}
    			</output>
			</plugin>
			
						<!-- Moving Left-->
			<plugin filename="gz-sim-triggered-publisher-system"
        			name="gz::sim::systems::TriggeredPublisher">
    			<input type="gz.msgs.Int32" topic="/keyboard/keypress">
        			<match field="data">16777234</match>
    			</input>
    			<output type="gz.msgs.Twist" topic="/cmd_vel">
        			linear: {x: 0.0}, angular: {z: 0.5}
    			</output>
			</plugin>
			
						<!-- Moving right-->
			<plugin filename="gz-sim-triggered-publisher-system"
        			name="gz::sim::systems::TriggeredPublisher">
    			<input type="gz.msgs.Int32" topic="/keyboard/keypress">
        			<match field="data">16777236</match>
    			</input>
    			<output type="gz.msgs.Twist" topic="/cmd_vel">
        			linear: {x: 0.0}, angular: {z: -0.5}
    			</output>
			</plugin>
			
			<!-- LIDAR CONFIG -->
			<frame name="lidar_frame" attached_to='lidar_housing'>
    			<pose>0.5 0.0 0.25 0.0 0.0 0.0</pose>
			</frame>
		</model>

		<!--POKOJ WAGON-->
		<model name='walls_p_wagon'>
    		<static>true</static>
    		<pose>0 0 2.5 0 0 0</pose>
    		<link name='dluga_sciana_1'>
        		<visual name='visual'>
            		<geometry>
                		<box>
                    		<size>0.5 36 5</size>
                		</box>
            		</geometry>
            		<material>
                		<ambient>0.969 0.910 1 1</ambient>
                		<diffuse>0.969 0.910 1 1</diffuse>
                		<specular>0.969 0.910 1 1</specular>
            		</material>
        		</visual>
        		<collision name='collision'>
            		<geometry>
                		<box>
                    		<size>0.5 36 5</size>
                		</box>
            		</geometry>
        		</collision>
				<pose>6 26 0 0 0 0</pose>
    		</link>

			<link name='dluga_sciana_2_fr_1'>
        		<visual name='visual'>
            		<geometry>
                		<box>
                    		<size>0.5 31 5</size>
                		</box>
            		</geometry>
            		<material>
                		<ambient>0.969 0.910 1 1</ambient>
                		<diffuse>0.969 0.910 1 1</diffuse>
                		<specular>0.969 0.910 1 1</specular>
            		</material>
        		</visual>
        		<collision name='collision'>
            		<geometry>
                		<box>
                    		<size>0.5 31 5</size>
                		</box>
            		</geometry>
        		</collision>
				<pose>-6 28.5 0 0 0 0</pose>
    		</link>

			<link name='dluga_sciana_2_fr_2'>
        		<visual name='visual'>
            		<geometry>
                		<box>
                    		<size>0.5 6 1</size>
                		</box>
            		</geometry>
            		<material>
                		<ambient>0.969 0.910 1 1</ambient>
                		<diffuse>0.969 0.910 1 1</diffuse>
                		<specular>0.969 0.910 1 1</specular>
            		</material>
        		</visual>
        		<collision name='collision'>
            		<geometry>
                		<box>
                    		<size>0.5 6 1</size>
                		</box>
            		</geometry>
        		</collision>
				<pose>-6 12 2 0 0 0</pose>
    		</link>

			<link name='dluga_sciana_2_fr_3'>
        		<visual name='visual'>
            		<geometry>
                		<box>
                    		<size>0.5 1 5</size>
                		</box>
            		</geometry>
            		<material>
                		<ambient>0.969 0.910 1 1</ambient>
                		<diffuse>0.969 0.910 1 1</diffuse>
                		<specular>0.969 0.910 1 1</specular>
            		</material>
        		</visual>
        		<collision name='collision'>
            		<geometry>
                		<box>
                    		<size>0.5 2 5</size>
                		</box>
            		</geometry>
        		</collision>
				<pose>-6 8.5 0 0 0 0</pose>
    		</link>

    		<link name='krotka_sciana_1'>
        		<visual name='visual'>
            		<geometry>
                		<box>
                    		<size>0.5 12 5</size>
                		</box>
            		</geometry>
            		<material>
                		<ambient>0.969 0.910 1 1</ambient>
                		<diffuse>0.969 0.910 1 1</diffuse>
                		<specular>0.969 0.910 1 1</specular>
            		</material>
        		</visual>
        		<collision name='collision'>
            		<geometry>
                		<box>
                    		<size>0.5 12 5</size>
                		</box>
            		</geometry>
        		</collision>
				<pose>0 44 0 0 0 1.57</pose>
    		</link>
		</model>

		<!-- scianka w malym pokoju z drzwiami-->
		<model name='wall_p_m_1'>
    		<static>true</static>
    		<pose>6 0 2.5 0 0 0</pose>
    		<link name='box'>
        		<visual name='visual'>
            		<geometry>
                		<box>
                    		<size>0.5 16 5</size>
                		</box>
            		</geometry>
            		<material>
                		<ambient>1 0.949 0.733 1</ambient>
                		<diffuse>1 0.949 0.733 1</diffuse>
                		<specular>1 0.949 0.733 1</specular>
            		</material>
        		</visual>
        		<collision name='collision'>
            		<geometry>
                		<box>
                    		<size>0.5 16 5</size>
                		</box>
            		</geometry>
        		</collision>
    		</link>
		</model>
		
		<!-- scianka w malym pokoju z drzwiami-->
		<model name='wall_p_m_2'>
    		<static>true</static>
    		<pose>-6 0 2.5 0 0 0</pose>
    		<link name='wall_fragment_1'>
        		<visual name='visual'>
            		<geometry>
                		<box>
                    		<size>0.5 10 5</size>
                		</box>
            		</geometry>
            		<material>
                		<ambient>1 0.949 0.733 1</ambient>
                		<diffuse>1 0.949 0.733 1</diffuse>
                		<specular>1 0.949 0.733 1</specular>
            		</material>
        		</visual>
        		<collision name='collision'>
            		<geometry>
                		<box>
                    		<size>0.5 10 5</size>
                		</box>
            		</geometry>
        		</collision>
				<pose>0 -3 0 0 0 0</pose>
    		</link>

			<link name='wall_fragment_2'>
        		<visual name='visual'>
            		<geometry>
                		<box>
                    		<size>0.5 6 1</size>
                		</box>
            		</geometry>
            		<material>
                		<ambient>1 0.949 0.733 1</ambient>
                		<diffuse>1 0.949 0.733 1</diffuse>
                		<specular>1 0.949 0.733 1</specular>
            		</material>
        		</visual>
        		<collision name='collision'>
            		<geometry>
                		<box>
                    		<size>0.5 6 1</size>
                		</box>
            		</geometry>
        		</collision>
				<pose>0 4 2 0 0 0</pose>
    		</link>

			<link name='wall_fragment_3'>
        		<visual name='visual'>
            		<geometry>
                		<box>
                    		<size>0.5 2 5</size>
                		</box>
            		</geometry>
            		<material>
                		<ambient>1 0.949 0.733 1</ambient>
                		<diffuse>1 0.949 0.733 1</diffuse>
                		<specular>1 0.949 0.733 1</specular>
            		</material>
        		</visual>
        		<collision name='collision'>
            		<geometry>
                		<box>
                    		<size>0.5 2 5</size>
                		</box>
            		</geometry>
        		</collision>
				<pose>0 7 0 0 0 0</pose>
    		</link>
		</model>

		<model name='wall_p_m_3'>
    		<static>true</static>
    		<pose>0 8 2.5 0 0 1.57</pose>
    		<link name='box'>
        		<visual name='visual'>
            		<geometry>
                		<box>
                    		<size>0.5 12 5</size>
                		</box>
            		</geometry>
            		<material>
                		<ambient>1 0.949 0.733 1</ambient>
                		<diffuse>1 0.949 0.733 1</diffuse>
                		<specular>1 0.949 0.733 1</specular>
            		</material>
        		</visual>
        		<collision name='collision'>
            		<geometry>
                		<box>
                    		<size>0.5 12 5</size>
                		</box>
            		</geometry>
        		</collision>
    		</link>
		</model>

		<model name='wall_p_m_4'>
    		<static>true</static>
    		<pose>0 -8 2.5 0 0 1.57</pose>
    		<link name='box'>
        		<visual name='visual'>
            		<geometry>
                		<box>
                    		<size>0.5 12 5</size>
                		</box>
            		</geometry>
            		<material>
                		<ambient>1 0.949 0.733 1</ambient>
                		<diffuse>1 0.949 0.733 1</diffuse>
                		<specular>1 0.949 0.733 1</specular>
            		</material>
        		</visual>
        		<collision name='collision'>
            		<geometry>
                		<box>
                    		<size>0.5 12 5</size>
                		</box>
            		</geometry>
        		</collision>
    		</link>
		</model>

		<model name='korytarz'>
    		<static>true</static>
			<pose>0 0 2.5 0 0 0</pose>
    		<link name='scianka_korytarz_salon'>
        		<visual name='visual'>
            		<geometry>
                		<box>
                    		<size>0.5 20 5</size>
                		</box>
            		</geometry>
            		<material>
                		<ambient>0.843 0.984 0.820 1.0</ambient>
                		<diffuse>0.843 0.984 0.820 1.0</diffuse>
                		<specular>0.843 0.984 0.820 1.0</specular>
            		</material>
        		</visual>
        		<collision name='collision'>
            		<geometry>
                		<box>
                    		<size>0.5 20 5</size>
                		</box>
            		</geometry>
        		</collision>
				<pose>-18 16 0 0 0 1.57</pose>
    		</link>

			<link name='scianka_korytarz_wyjscie'>
        		<visual name='visual'>
            		<geometry>
                		<box>
                    		<size>0.5 8 5</size>
                		</box>
            		</geometry>
            		<material>
                		<ambient>0.843 0.984 0.820 1.0</ambient>
                		<diffuse>0.843 0.984 0.820 1.0</diffuse>
                		<specular>0.843 0.984 0.820 1.0</specular>
            		</material>
        		</visual>
        		<collision name='collision'>
            		<geometry>
                		<box>
                    		<size>0.5 8 5</size>
                		</box>
            		</geometry>
        		</collision>
				<pose>-26 12 0 0 0 0</pose>
    		</link>

			<link name='scianka_korytarz_lazienka_1'>
        		<visual name='visual'>
            		<geometry>
                		<box>
                    		<size>0.5 9 5</size>
                		</box>
            		</geometry>
            		<material>
                		<ambient>0.843 0.984 0.820 1.0</ambient>
                		<diffuse>0.843 0.984 0.820 1.0</diffuse>
                		<specular>0.843 0.984 0.820 1.0</specular>
            		</material>
        		</visual>
        		<collision name='collision'>
            		<geometry>
                		<box>
                    		<size>0.5 9 5</size>
                		</box>
            		</geometry>
        		</collision>
				<pose>-21.5 8 0 0 0 1.57</pose>
    		</link>

			<link name='scianka_korytarz_lazienka_2'>
        		<visual name='visual'>
            		<geometry>
                		<box>
                    		<size>0.5 8 5</size>
                		</box>
            		</geometry>
            		<material>
                		<ambient>0.843 0.984 0.820 1.0</ambient>
                		<diffuse>0.843 0.984 0.820 1.0</diffuse>
                		<specular>0.843 0.984 0.820 1.0</specular>
            		</material>
        		</visual>
        		<collision name='collision'>
            		<geometry>
                		<box>
                    		<size>0.5 8 5</size>
                		</box>
            		</geometry>
        		</collision>
				<pose>-13 4 0 0 0 0</pose>
    		</link>

		</model>

    </world>
</sdf>
