<?xml version="1.0" ?>
<sdf version="1.11">
  <model name="pendulum">
    <link name="base">
      <inertial auto="true" />
      <visual name="vis_plate_on_ground">
        <pose>-0.0 0.001 0.0005 0 0 0</pose>
        <geometry>
          <box>
            <size>0.2 0.5 0.015</size>   
            <scale>7 7 7</scale>
          </box>  
        </geometry>
        <material>
          <ambient>1 1 1 1</ambient>
          <diffuse>1 1 1 1</diffuse>
          <specular>1 1 1 1</specular>
          <pbr>
            <metal>
              <albedo_map>materials/Wood/Wood_COLOR.jpg</albedo_map>
              <normal_map>materials/Wood/Wood_NORM.jpg</normal_map>
              <roughness_map>materials/Wood/Wood_ROUGH.jpg</roughness_map>
            </metal>
          </pbr>
        </material>
      </visual>
      <visual name="vis_pole">
        <pose>-0.01375 0.0819 0.225 0.349 0 0</pose>
        <geometry>
          <cylinder>
            <length>0.4788</length>
            <radius>0.007</radius>
            <scale>7 7 7</scale>
          </cylinder>
        </geometry>
        <material>
          <ambient>0.66 1 1 1</ambient>
          <diffuse>0.66 1 1 1</diffuse>
          <specular>0.66 1 1 1</specular>
          <pbr>
            <metal>
              <metalness>0.9</metalness>
            </metal>
          </pbr>
        </material>
      </visual>
      <visual name="vis_pole2">
        <pose>-0.01375 -0.0819 0.225 -0.349 0 0</pose>
        <geometry>
          <cylinder>
            <length>0.4788</length>
            <radius>0.007</radius>
            <scale>7 7 7</scale>
          </cylinder>
        </geometry>
        <material>
          <ambient>0.66 1 1 1</ambient>
          <diffuse>0.66 1 1 1</diffuse>
          <specular>0.66 1 1 1</specular>
          <pbr>
            <metal>
              <metalness>0.9</metalness>
            </metal>
          </pbr>
        </material>
      </visual>
      <collision name="col_plate_on_ground">
        <density>2710.0</density>
        <pose>-0.0 0.001 0.0005 0 0 0</pose>
        <geometry>
          <box>
            <size>0.2 0.5 0.015</size>
            <scale>7 7 7</scale>
          </box>
        </geometry>
      </collision>
      <collision name="col_pole">
        <density>2710</density>
        <pose>-0.01375 0.0819 0.225 0.349 0 0</pose>
        <geometry>
          <cylinder>
            <length>0.4788</length>
            <radius>0.007</radius>
            <scale>7 7 7</scale>
          </cylinder>
        </geometry>
      </collision>
      <collision name="col_pole2">
        <density>2710</density>
        <pose>-0.01375 -0.0819 0.225 -0.349 0 0</pose>
        <geometry>
          <cylinder>
            <length>0.4788</length>
            <radius>0.007</radius>
            <scale>7 7 7</scale>
          </cylinder>
        </geometry>
      </collision>
    </link>

    <!-- upper link, length 1, IC -90 degrees -->
    <link name="upper_link">
      <pose>0 0.017 0.355 0.2 0 0</pose>
      <self_collide>0</self_collide>
      <inertial auto="true" />
      <visual name="vis_upper_joint">
        <pose>-0.0025 0 0.0875 0 1.5708 0</pose>
        <geometry>
          <cylinder>
            <radius>0.005</radius>
            <length>0.015</length>
            <scale>7 7 7</scale>
          </cylinder>
        </geometry>
        <material>
          <ambient>0.66 1 1 1</ambient>
          <diffuse>0.66 1 1 1</diffuse>
          <specular>0.66 1 1 1</specular>
          <pbr>
            <metal>
              <metalness>0.9</metalness>
            </metal>
          </pbr>
        </material>
      </visual>
      <visual name="vis_bob2">
        <pose>0.010 0 0.20 0 1.5708 0</pose>
        <geometry>
          <cylinder>
            <radius>0.005</radius>
            <length>0.02</length>
            <scale>7 7 7</scale>
          </cylinder>
        </geometry>
        <material>
          <ambient>0.66 1 1 1</ambient>
          <diffuse>0.66 1 1 1</diffuse>
          <specular>0.66 1 1 1</specular>
          <pbr>
            <metal>
              <metalness>0.9</metalness>
            </metal>
          </pbr>
        </material>
      </visual>
      <visual name="vis_cylinder">
        <pose>0.01 0 0 0 0 0</pose>
        <geometry>
          <cylinder>
            <radius>0.005</radius>
            <length>0.395</length>
            <scale>7 7 7</scale>
          </cylinder>
        </geometry>
        <material>
          <ambient>0.66 1 1 1</ambient>
          <diffuse>0.66 1 1 1</diffuse>
          <specular>0.66 1 1 1</specular>
          <pbr>
            <metal>
              <metalness>0.9</metalness>
            </metal>
          </pbr>
        </material>
      </visual>
      <collision name="col_upper_joint">
        <density>2710</density>
        <pose>-0.0025 0 0.0875 0 1.5708 0</pose>
        <geometry>
          <cylinder>
            <radius>0.01</radius>
            <length>0.015</length>
            <scale>7 7 7</scale>
          </cylinder>
        </geometry>
      </collision>
      <collision name="col_bob2">
        <density>2710</density>
        <pose>0.010 0 0.207 0 1.5708 0</pose>
        <geometry>
          <cylinder>
            <radius>0.01</radius>
            <length>0.02</length>
            <scale>7 7 7</scale>
          </cylinder>
        </geometry>
      </collision>
      <collision name="col_cylinder">
        <density>2710</density>
        <pose>0.01 0 0 0 0 0</pose>
        <geometry>
          <cylinder>
            <radius>0.005</radius>
            <length>0.395</length>
            <scale>7 7 7</scale>
          </cylinder>
        </geometry>
      </collision>
    </link>

    <!-- lower link, length 1, IC ~-120 degrees more -->
    <link name="lower_link">
      <pose>0.025 -0.02 0.55 -1.57 0 0</pose>
      <self_collide>0</self_collide>
      <inertial auto="true" />
      <visual name="vis_cylinder">
        <pose>0 0 0.025 0 0 0</pose>
        <geometry>
          <cylinder>
            <radius>0.005</radius>
            <length>0.30</length>
            <scale>7 7 7</scale>
          </cylinder>
        </geometry>
        <material>
          <ambient>0.66 1 1 1</ambient>
          <diffuse>0.66 1 1 1</diffuse>
          <specular>0.66 1 1 1</specular>
          <pbr>
            <metal>
              <metalness>0.9</metalness>
            </metal>
          </pbr>
        </material>
      </visual>
      <collision name="col_cylinder">
        <density>2710</density>
        <pose>0 0 0.025 0 0 0</pose>
        <geometry>
          <cylinder>
            <radius>0.005</radius>
            <length>0.30</length>
            <scale>7 7 7</scale>
          </cylinder>
        </geometry>
      </collision>
    </link>
      
    <!-- pin joint for upper link, at origin of upper link -->
    <joint name="upper_joint" type="revolute">
      <pose>-0.0025 0 0.0875 0 0 0</pose>
      <parent>base</parent>
      <child>upper_link</child>
      <axis>
        <xyz>1.0 0 0</xyz>
      </axis>
    </joint>

    <!-- pin joint for lower link, at origin of child link -->
    <joint name="lower_joint" type="revolute">
      <pose relative_to="upper_link">0.010 0 0.20 0 0 0</pose>
      <parent>upper_link</parent>
      <child>lower_link</child>
      <axis>
        <xyz>1.0 0 0</xyz>
      </axis>
    </joint>
  </model>
</sdf>
